[2023-11-03T11:00:21.364+0000] {taskinstance.py:1157} INFO - Dependencies all met for dep_context=non-requeueable deps ti=<TaskInstance: movies-etl-dag.get_films_data manual__2023-11-03T11:00:15.146185+00:00 [queued]>
[2023-11-03T11:00:21.374+0000] {taskinstance.py:1157} INFO - Dependencies all met for dep_context=requeueable deps ti=<TaskInstance: movies-etl-dag.get_films_data manual__2023-11-03T11:00:15.146185+00:00 [queued]>
[2023-11-03T11:00:21.375+0000] {taskinstance.py:1359} INFO - Starting attempt 1 of 1
[2023-11-03T11:00:21.394+0000] {taskinstance.py:1380} INFO - Executing <Task(PythonOperator): get_films_data> on 2023-11-03 11:00:15.146185+00:00
[2023-11-03T11:00:21.402+0000] {standard_task_runner.py:57} INFO - Started process 545 to run task
[2023-11-03T11:00:21.406+0000] {standard_task_runner.py:84} INFO - Running: ['***', 'tasks', 'run', 'movies-etl-dag', 'get_films_data', 'manual__2023-11-03T11:00:15.146185+00:00', '--job-id', '41', '--raw', '--subdir', 'DAGS_FOLDER/movie_pg_es.py', '--cfg-path', '/tmp/tmp8bp8o57w']
[2023-11-03T11:00:21.409+0000] {standard_task_runner.py:85} INFO - Job 41: Subtask get_films_data
[2023-11-03T11:00:21.605+0000] {task_command.py:415} INFO - Running <TaskInstance: movies-etl-dag.get_films_data manual__2023-11-03T11:00:15.146185+00:00 [running]> on host e468bf2dfd15
[2023-11-03T11:00:21.925+0000] {taskinstance.py:1660} INFO - Exporting env vars: AIRFLOW_CTX_DAG_OWNER='***' AIRFLOW_CTX_DAG_ID='movies-etl-dag' AIRFLOW_CTX_TASK_ID='get_films_data' AIRFLOW_CTX_EXECUTION_DATE='2023-11-03T11:00:15.146185+00:00' AIRFLOW_CTX_TRY_NUMBER='1' AIRFLOW_CTX_DAG_RUN_ID='manual__2023-11-03T11:00:15.146185+00:00'
[2023-11-03T11:00:22.027+0000] {base.py:73} INFO - Using connection ID 'movies_db_id' for task execution.
[2023-11-03T11:00:22.078+0000] {taskinstance.py:1935} ERROR - Task failed with exception
Traceback (most recent call last):
  File "/home/airflow/.local/lib/python3.8/site-packages/airflow/operators/python.py", line 192, in execute
    return_value = self.execute_callable()
  File "/home/airflow/.local/lib/python3.8/site-packages/airflow/operators/python.py", line 209, in execute_callable
    return self.python_callable(*self.op_args, **self.op_kwargs)
  File "/opt/airflow/dags/movie_pg_es.py", line 97, in get_films_data
    items = [FilmWork(*rec).dict() for rec in cursor.fetchall()]
  File "/opt/airflow/dags/movie_pg_es.py", line 97, in <listcomp>
    items = [FilmWork(*rec).dict() for rec in cursor.fetchall()]
TypeError: __init__() takes 1 positional argument but 12 were given
[2023-11-03T11:00:22.125+0000] {taskinstance.py:1398} INFO - Marking task as FAILED. dag_id=movies-etl-dag, task_id=get_films_data, execution_date=20231103T110015, start_date=20231103T110021, end_date=20231103T110022
[2023-11-03T11:00:22.150+0000] {standard_task_runner.py:104} ERROR - Failed to execute job 41 for task get_films_data (__init__() takes 1 positional argument but 12 were given; 545)
[2023-11-03T11:00:22.179+0000] {local_task_job_runner.py:228} INFO - Task exited with return code 1
[2023-11-03T11:00:22.253+0000] {taskinstance.py:2776} INFO - 0 downstream tasks scheduled from follow-on schedule check
