[2023-11-03T13:13:52.133+0000] {taskinstance.py:1157} INFO - Dependencies all met for dep_context=non-requeueable deps ti=<TaskInstance: movies-etl-dag.write_to_es manual__2023-11-03T13:13:41.300124+00:00 [queued]>
[2023-11-03T13:13:52.142+0000] {taskinstance.py:1157} INFO - Dependencies all met for dep_context=requeueable deps ti=<TaskInstance: movies-etl-dag.write_to_es manual__2023-11-03T13:13:41.300124+00:00 [queued]>
[2023-11-03T13:13:52.143+0000] {taskinstance.py:1359} INFO - Starting attempt 1 of 1
[2023-11-03T13:13:52.158+0000] {taskinstance.py:1380} INFO - Executing <Task(PythonOperator): write_to_es> on 2023-11-03 13:13:41.300124+00:00
[2023-11-03T13:13:52.164+0000] {standard_task_runner.py:57} INFO - Started process 2639 to run task
[2023-11-03T13:13:52.167+0000] {standard_task_runner.py:84} INFO - Running: ['***', 'tasks', 'run', 'movies-etl-dag', 'write_to_es', 'manual__2023-11-03T13:13:41.300124+00:00', '--job-id', '84', '--raw', '--subdir', 'DAGS_FOLDER/movie_pg_es.py', '--cfg-path', '/tmp/tmp3sxvj_7d']
[2023-11-03T13:13:52.171+0000] {standard_task_runner.py:85} INFO - Job 84: Subtask write_to_es
[2023-11-03T13:13:52.353+0000] {task_command.py:415} INFO - Running <TaskInstance: movies-etl-dag.write_to_es manual__2023-11-03T13:13:41.300124+00:00 [running]> on host e468bf2dfd15
[2023-11-03T13:13:52.620+0000] {taskinstance.py:1660} INFO - Exporting env vars: AIRFLOW_CTX_DAG_OWNER='***' AIRFLOW_CTX_DAG_ID='movies-etl-dag' AIRFLOW_CTX_TASK_ID='write_to_es' AIRFLOW_CTX_EXECUTION_DATE='2023-11-03T13:13:41.300124+00:00' AIRFLOW_CTX_TRY_NUMBER='1' AIRFLOW_CTX_DAG_RUN_ID='manual__2023-11-03T13:13:41.300124+00:00'
[2023-11-03T13:13:52.668+0000] {taskinstance.py:1935} ERROR - Task failed with exception
Traceback (most recent call last):
  File "/home/airflow/.local/lib/python3.8/site-packages/airflow/operators/python.py", line 192, in execute
    return_value = self.execute_callable()
  File "/home/airflow/.local/lib/python3.8/site-packages/airflow/operators/python.py", line 209, in execute_callable
    return self.python_callable(*self.op_args, **self.op_kwargs)
  File "/opt/airflow/dags/movie_pg_es.py", line 113, in write_to_es
    films_data = [FilmWork(**json.loads(film_data)) for film_data in films_data]
  File "/opt/airflow/dags/movie_pg_es.py", line 113, in <listcomp>
    films_data = [FilmWork(**json.loads(film_data)) for film_data in films_data]
  File "/opt/airflow/dags/models.py", line 30, in __init__
    data["actors_ids"], data["actors_names"] = self.split_person_str(data["actors"])
KeyError: 'actors'
[2023-11-03T13:13:52.717+0000] {taskinstance.py:1398} INFO - Marking task as FAILED. dag_id=movies-etl-dag, task_id=write_to_es, execution_date=20231103T131341, start_date=20231103T131352, end_date=20231103T131352
[2023-11-03T13:13:52.732+0000] {standard_task_runner.py:104} ERROR - Failed to execute job 84 for task write_to_es ('actors'; 2639)
[2023-11-03T13:13:52.740+0000] {local_task_job_runner.py:228} INFO - Task exited with return code 1
[2023-11-03T13:13:52.803+0000] {taskinstance.py:2776} INFO - 0 downstream tasks scheduled from follow-on schedule check
