[2023-11-03T11:00:19.754+0000] {taskinstance.py:1157} INFO - Dependencies all met for dep_context=non-requeueable deps ti=<TaskInstance: movies-etl-dag.get_films_data scheduled__2023-11-03T10:59:06.351955+00:00 [queued]>
[2023-11-03T11:00:19.763+0000] {taskinstance.py:1157} INFO - Dependencies all met for dep_context=requeueable deps ti=<TaskInstance: movies-etl-dag.get_films_data scheduled__2023-11-03T10:59:06.351955+00:00 [queued]>
[2023-11-03T11:00:19.764+0000] {taskinstance.py:1359} INFO - Starting attempt 1 of 1
[2023-11-03T11:00:19.783+0000] {taskinstance.py:1380} INFO - Executing <Task(PythonOperator): get_films_data> on 2023-11-03 10:59:06.351955+00:00
[2023-11-03T11:00:19.790+0000] {standard_task_runner.py:57} INFO - Started process 535 to run task
[2023-11-03T11:00:19.793+0000] {standard_task_runner.py:84} INFO - Running: ['***', 'tasks', 'run', 'movies-etl-dag', 'get_films_data', 'scheduled__2023-11-03T10:59:06.351955+00:00', '--job-id', '40', '--raw', '--subdir', 'DAGS_FOLDER/movie_pg_es.py', '--cfg-path', '/tmp/tmp255euig6']
[2023-11-03T11:00:19.797+0000] {standard_task_runner.py:85} INFO - Job 40: Subtask get_films_data
[2023-11-03T11:00:20.009+0000] {task_command.py:415} INFO - Running <TaskInstance: movies-etl-dag.get_films_data scheduled__2023-11-03T10:59:06.351955+00:00 [running]> on host e468bf2dfd15
[2023-11-03T11:00:20.328+0000] {taskinstance.py:1660} INFO - Exporting env vars: AIRFLOW_CTX_DAG_OWNER='***' AIRFLOW_CTX_DAG_ID='movies-etl-dag' AIRFLOW_CTX_TASK_ID='get_films_data' AIRFLOW_CTX_EXECUTION_DATE='2023-11-03T10:59:06.351955+00:00' AIRFLOW_CTX_TRY_NUMBER='1' AIRFLOW_CTX_DAG_RUN_ID='scheduled__2023-11-03T10:59:06.351955+00:00'
[2023-11-03T11:00:20.452+0000] {base.py:73} INFO - Using connection ID 'movies_db_id' for task execution.
[2023-11-03T11:00:20.527+0000] {taskinstance.py:1935} ERROR - Task failed with exception
Traceback (most recent call last):
  File "/home/airflow/.local/lib/python3.8/site-packages/airflow/operators/python.py", line 192, in execute
    return_value = self.execute_callable()
  File "/home/airflow/.local/lib/python3.8/site-packages/airflow/operators/python.py", line 209, in execute_callable
    return self.python_callable(*self.op_args, **self.op_kwargs)
  File "/opt/airflow/dags/movie_pg_es.py", line 97, in get_films_data
    items = [FilmWork(*rec).dict() for rec in cursor.fetchall()]
  File "/opt/airflow/dags/movie_pg_es.py", line 97, in <listcomp>
    items = [FilmWork(*rec).dict() for rec in cursor.fetchall()]
TypeError: __init__() takes 1 positional argument but 12 were given
[2023-11-03T11:00:20.594+0000] {taskinstance.py:1398} INFO - Marking task as FAILED. dag_id=movies-etl-dag, task_id=get_films_data, execution_date=20231103T105906, start_date=20231103T110019, end_date=20231103T110020
[2023-11-03T11:00:20.623+0000] {standard_task_runner.py:104} ERROR - Failed to execute job 40 for task get_films_data (__init__() takes 1 positional argument but 12 were given; 535)
[2023-11-03T11:00:20.647+0000] {local_task_job_runner.py:228} INFO - Task exited with return code 1
[2023-11-03T11:00:20.743+0000] {taskinstance.py:2776} INFO - 0 downstream tasks scheduled from follow-on schedule check
