[2023-11-03T13:57:32.739+0000] {taskinstance.py:1157} INFO - Dependencies all met for dep_context=non-requeueable deps ti=<TaskInstance: movies-etl-dag.preprocess_data scheduled__2023-11-03T13:56:23.927579+00:00 [queued]>
[2023-11-03T13:57:32.747+0000] {taskinstance.py:1157} INFO - Dependencies all met for dep_context=requeueable deps ti=<TaskInstance: movies-etl-dag.preprocess_data scheduled__2023-11-03T13:56:23.927579+00:00 [queued]>
[2023-11-03T13:57:32.748+0000] {taskinstance.py:1359} INFO - Starting attempt 1 of 1
[2023-11-03T13:57:32.762+0000] {taskinstance.py:1380} INFO - Executing <Task(PythonOperator): preprocess_data> on 2023-11-03 13:56:23.927579+00:00
[2023-11-03T13:57:32.768+0000] {standard_task_runner.py:57} INFO - Started process 3518 to run task
[2023-11-03T13:57:32.772+0000] {standard_task_runner.py:84} INFO - Running: ['***', 'tasks', 'run', 'movies-etl-dag', 'preprocess_data', 'scheduled__2023-11-03T13:56:23.927579+00:00', '--job-id', '157', '--raw', '--subdir', 'DAGS_FOLDER/movie_pg_es.py', '--cfg-path', '/tmp/tmps8czw35g']
[2023-11-03T13:57:32.775+0000] {standard_task_runner.py:85} INFO - Job 157: Subtask preprocess_data
[2023-11-03T13:57:32.948+0000] {task_command.py:415} INFO - Running <TaskInstance: movies-etl-dag.preprocess_data scheduled__2023-11-03T13:56:23.927579+00:00 [running]> on host e468bf2dfd15
[2023-11-03T13:57:33.208+0000] {taskinstance.py:1660} INFO - Exporting env vars: AIRFLOW_CTX_DAG_OWNER='***' AIRFLOW_CTX_DAG_ID='movies-etl-dag' AIRFLOW_CTX_TASK_ID='preprocess_data' AIRFLOW_CTX_EXECUTION_DATE='2023-11-03T13:56:23.927579+00:00' AIRFLOW_CTX_TRY_NUMBER='1' AIRFLOW_CTX_DAG_RUN_ID='scheduled__2023-11-03T13:56:23.927579+00:00'
[2023-11-03T13:57:33.274+0000] {taskinstance.py:1935} ERROR - Task failed with exception
Traceback (most recent call last):
  File "/home/airflow/.local/lib/python3.8/site-packages/airflow/operators/python.py", line 192, in execute
    return_value = self.execute_callable()
  File "/home/airflow/.local/lib/python3.8/site-packages/airflow/operators/python.py", line 209, in execute_callable
    return self.python_callable(*self.op_args, **self.op_kwargs)
  File "/opt/airflow/dags/movie_pg_es.py", line 115, in preprocess_data
    film_data = FilmWorkPG(**json.loads(film_data))
  File "/opt/airflow/dags/models.py", line 30, in __init__
    data["actors_ids"], data["actors_names"] = self.split_person_str(data["actors"])
KeyError: 'actors'
[2023-11-03T13:57:33.337+0000] {taskinstance.py:1398} INFO - Marking task as FAILED. dag_id=movies-etl-dag, task_id=preprocess_data, execution_date=20231103T135623, start_date=20231103T135732, end_date=20231103T135733
[2023-11-03T13:57:33.358+0000] {standard_task_runner.py:104} ERROR - Failed to execute job 157 for task preprocess_data ('actors'; 3518)
[2023-11-03T13:57:33.425+0000] {local_task_job_runner.py:228} INFO - Task exited with return code 1
[2023-11-03T13:57:33.493+0000] {taskinstance.py:2776} INFO - 0 downstream tasks scheduled from follow-on schedule check
