[2023-11-03T11:06:59.029+0000] {taskinstance.py:1157} INFO - Dependencies all met for dep_context=non-requeueable deps ti=<TaskInstance: movies-etl-dag.get_films_data manual__2023-11-03T11:06:52.162248+00:00 [queued]>
[2023-11-03T11:06:59.038+0000] {taskinstance.py:1157} INFO - Dependencies all met for dep_context=requeueable deps ti=<TaskInstance: movies-etl-dag.get_films_data manual__2023-11-03T11:06:52.162248+00:00 [queued]>
[2023-11-03T11:06:59.039+0000] {taskinstance.py:1359} INFO - Starting attempt 1 of 1
[2023-11-03T11:06:59.062+0000] {taskinstance.py:1380} INFO - Executing <Task(PythonOperator): get_films_data> on 2023-11-03 11:06:52.162248+00:00
[2023-11-03T11:06:59.068+0000] {standard_task_runner.py:57} INFO - Started process 690 to run task
[2023-11-03T11:06:59.072+0000] {standard_task_runner.py:84} INFO - Running: ['***', 'tasks', 'run', 'movies-etl-dag', 'get_films_data', 'manual__2023-11-03T11:06:52.162248+00:00', '--job-id', '57', '--raw', '--subdir', 'DAGS_FOLDER/movie_pg_es.py', '--cfg-path', '/tmp/tmp5nw85o4b']
[2023-11-03T11:06:59.075+0000] {standard_task_runner.py:85} INFO - Job 57: Subtask get_films_data
[2023-11-03T11:06:59.234+0000] {task_command.py:415} INFO - Running <TaskInstance: movies-etl-dag.get_films_data manual__2023-11-03T11:06:52.162248+00:00 [running]> on host e468bf2dfd15
[2023-11-03T11:06:59.550+0000] {taskinstance.py:1660} INFO - Exporting env vars: AIRFLOW_CTX_DAG_OWNER='***' AIRFLOW_CTX_DAG_ID='movies-etl-dag' AIRFLOW_CTX_TASK_ID='get_films_data' AIRFLOW_CTX_EXECUTION_DATE='2023-11-03T11:06:52.162248+00:00' AIRFLOW_CTX_TRY_NUMBER='1' AIRFLOW_CTX_DAG_RUN_ID='manual__2023-11-03T11:06:52.162248+00:00'
[2023-11-03T11:06:59.646+0000] {base.py:73} INFO - Using connection ID 'movies_db_id' for task execution.
[2023-11-03T11:06:59.694+0000] {taskinstance.py:1935} ERROR - Task failed with exception
Traceback (most recent call last):
  File "/home/airflow/.local/lib/python3.8/site-packages/airflow/operators/python.py", line 192, in execute
    return_value = self.execute_callable()
  File "/home/airflow/.local/lib/python3.8/site-packages/airflow/operators/python.py", line 209, in execute_callable
    return self.python_callable(*self.op_args, **self.op_kwargs)
  File "/opt/airflow/dags/movie_pg_es.py", line 99, in get_films_data
    return json.dumps(items, indent=4)
  File "/usr/local/lib/python3.8/json/__init__.py", line 234, in dumps
    return cls(
  File "/usr/local/lib/python3.8/json/encoder.py", line 201, in encode
    chunks = list(chunks)
  File "/usr/local/lib/python3.8/json/encoder.py", line 429, in _iterencode
    yield from _iterencode_list(o, _current_indent_level)
  File "/usr/local/lib/python3.8/json/encoder.py", line 325, in _iterencode_list
    yield from chunks
  File "/usr/local/lib/python3.8/json/encoder.py", line 405, in _iterencode_dict
    yield from chunks
  File "/usr/local/lib/python3.8/json/encoder.py", line 438, in _iterencode
    o = _default(o)
  File "/usr/local/lib/python3.8/json/encoder.py", line 179, in default
    raise TypeError(f'Object of type {o.__class__.__name__} '
TypeError: Object of type datetime is not JSON serializable
[2023-11-03T11:06:59.739+0000] {taskinstance.py:1398} INFO - Marking task as FAILED. dag_id=movies-etl-dag, task_id=get_films_data, execution_date=20231103T110652, start_date=20231103T110659, end_date=20231103T110659
[2023-11-03T11:06:59.754+0000] {standard_task_runner.py:104} ERROR - Failed to execute job 57 for task get_films_data (Object of type datetime is not JSON serializable; 690)
[2023-11-03T11:06:59.766+0000] {local_task_job_runner.py:228} INFO - Task exited with return code 1
[2023-11-03T11:06:59.831+0000] {taskinstance.py:2776} INFO - 0 downstream tasks scheduled from follow-on schedule check
