[2023-11-03T10:43:25.039+0000] {taskinstance.py:1157} INFO - Dependencies all met for dep_context=non-requeueable deps ti=<TaskInstance: movies-etl-dag.get_updated_movies_ids scheduled__2023-11-03T10:42:21.125140+00:00 [queued]>
[2023-11-03T10:43:25.050+0000] {taskinstance.py:1157} INFO - Dependencies all met for dep_context=requeueable deps ti=<TaskInstance: movies-etl-dag.get_updated_movies_ids scheduled__2023-11-03T10:42:21.125140+00:00 [queued]>
[2023-11-03T10:43:25.050+0000] {taskinstance.py:1359} INFO - Starting attempt 1 of 1
[2023-11-03T10:43:25.069+0000] {taskinstance.py:1380} INFO - Executing <Task(PythonOperator): get_updated_movies_ids> on 2023-11-03 10:42:21.125140+00:00
[2023-11-03T10:43:25.075+0000] {standard_task_runner.py:57} INFO - Started process 215 to run task
[2023-11-03T10:43:25.080+0000] {standard_task_runner.py:84} INFO - Running: ['***', 'tasks', 'run', 'movies-etl-dag', 'get_updated_movies_ids', 'scheduled__2023-11-03T10:42:21.125140+00:00', '--job-id', '17', '--raw', '--subdir', 'DAGS_FOLDER/movie_pg_es.py', '--cfg-path', '/tmp/tmps5jegn6h']
[2023-11-03T10:43:25.083+0000] {standard_task_runner.py:85} INFO - Job 17: Subtask get_updated_movies_ids
[2023-11-03T10:43:25.347+0000] {task_command.py:415} INFO - Running <TaskInstance: movies-etl-dag.get_updated_movies_ids scheduled__2023-11-03T10:42:21.125140+00:00 [running]> on host e468bf2dfd15
[2023-11-03T10:43:25.715+0000] {taskinstance.py:1660} INFO - Exporting env vars: AIRFLOW_CTX_DAG_OWNER='***' AIRFLOW_CTX_DAG_ID='movies-etl-dag' AIRFLOW_CTX_TASK_ID='get_updated_movies_ids' AIRFLOW_CTX_EXECUTION_DATE='2023-11-03T10:42:21.125140+00:00' AIRFLOW_CTX_TRY_NUMBER='1' AIRFLOW_CTX_DAG_RUN_ID='scheduled__2023-11-03T10:42:21.125140+00:00'
[2023-11-03T10:43:25.779+0000] {base.py:73} INFO - Using connection ID 'movies_db_id' for task execution.
[2023-11-03T10:43:33.785+0000] {taskinstance.py:1935} ERROR - Task failed with exception
Traceback (most recent call last):
  File "/home/airflow/.local/lib/python3.8/site-packages/airflow/operators/python.py", line 192, in execute
    return_value = self.execute_callable()
  File "/home/airflow/.local/lib/python3.8/site-packages/airflow/operators/python.py", line 209, in execute_callable
    return self.python_callable(*self.op_args, **self.op_kwargs)
  File "/opt/airflow/dags/movie_pg_es.py", line 47, in get_updated_movies_ids
    pg_conn = pg_hook.get_conn()
  File "/home/airflow/.local/lib/python3.8/site-packages/airflow/providers/postgres/hooks/postgres.py", line 154, in get_conn
    self.conn = psycopg2.connect(**conn_args)
  File "/home/airflow/.local/lib/python3.8/site-packages/psycopg2/__init__.py", line 122, in connect
    conn = _connect(dsn, connection_factory=connection_factory, **kwasync)
psycopg2.OperationalError: could not translate host name "movie_pg_db" to address: Temporary failure in name resolution

[2023-11-03T10:43:33.841+0000] {taskinstance.py:1398} INFO - Marking task as FAILED. dag_id=movies-etl-dag, task_id=get_updated_movies_ids, execution_date=20231103T104221, start_date=20231103T104325, end_date=20231103T104333
[2023-11-03T10:43:33.872+0000] {standard_task_runner.py:104} ERROR - Failed to execute job 17 for task get_updated_movies_ids (could not translate host name "movie_pg_db" to address: Temporary failure in name resolution
; 215)
[2023-11-03T10:43:33.911+0000] {local_task_job_runner.py:228} INFO - Task exited with return code 1
[2023-11-03T10:43:33.984+0000] {taskinstance.py:2776} INFO - 0 downstream tasks scheduled from follow-on schedule check
