[2023-11-03T10:35:50.126+0000] {taskinstance.py:1157} INFO - Dependencies all met for dep_context=non-requeueable deps ti=<TaskInstance: movies-etl-dag.get_updated_movies_ids scheduled__2023-11-03T10:34:21.125140+00:00 [queued]>
[2023-11-03T10:35:50.134+0000] {taskinstance.py:1157} INFO - Dependencies all met for dep_context=requeueable deps ti=<TaskInstance: movies-etl-dag.get_updated_movies_ids scheduled__2023-11-03T10:34:21.125140+00:00 [queued]>
[2023-11-03T10:35:50.134+0000] {taskinstance.py:1359} INFO - Starting attempt 1 of 1
[2023-11-03T10:35:50.150+0000] {taskinstance.py:1380} INFO - Executing <Task(PythonOperator): get_updated_movies_ids> on 2023-11-03 10:34:21.125140+00:00
[2023-11-03T10:35:50.156+0000] {standard_task_runner.py:57} INFO - Started process 76 to run task
[2023-11-03T10:35:50.161+0000] {standard_task_runner.py:84} INFO - Running: ['***', 'tasks', 'run', 'movies-etl-dag', 'get_updated_movies_ids', 'scheduled__2023-11-03T10:34:21.125140+00:00', '--job-id', '9', '--raw', '--subdir', 'DAGS_FOLDER/movie_pg_es.py', '--cfg-path', '/tmp/tmpaslqfq39']
[2023-11-03T10:35:50.164+0000] {standard_task_runner.py:85} INFO - Job 9: Subtask get_updated_movies_ids
[2023-11-03T10:35:50.339+0000] {task_command.py:415} INFO - Running <TaskInstance: movies-etl-dag.get_updated_movies_ids scheduled__2023-11-03T10:34:21.125140+00:00 [running]> on host e468bf2dfd15
[2023-11-03T10:35:50.596+0000] {taskinstance.py:1660} INFO - Exporting env vars: AIRFLOW_CTX_DAG_OWNER='***' AIRFLOW_CTX_DAG_ID='movies-etl-dag' AIRFLOW_CTX_TASK_ID='get_updated_movies_ids' AIRFLOW_CTX_EXECUTION_DATE='2023-11-03T10:34:21.125140+00:00' AIRFLOW_CTX_TRY_NUMBER='1' AIRFLOW_CTX_DAG_RUN_ID='scheduled__2023-11-03T10:34:21.125140+00:00'
[2023-11-03T10:35:50.686+0000] {taskinstance.py:1935} ERROR - Task failed with exception
Traceback (most recent call last):
  File "/home/airflow/.local/lib/python3.8/site-packages/airflow/operators/python.py", line 192, in execute
    return_value = self.execute_callable()
  File "/home/airflow/.local/lib/python3.8/site-packages/airflow/operators/python.py", line 209, in execute_callable
    return self.python_callable(*self.op_args, **self.op_kwargs)
  File "/opt/airflow/dags/movie_pg_es.py", line 47, in get_updated_movies_ids
    pg_conn = pg_hook.get_conn()
  File "/home/airflow/.local/lib/python3.8/site-packages/airflow/providers/postgres/hooks/postgres.py", line 124, in get_conn
    conn = deepcopy(self.connection or self.get_connection(conn_id))
  File "/home/airflow/.local/lib/python3.8/site-packages/airflow/hooks/base.py", line 72, in get_connection
    conn = Connection.get_connection_from_secrets(conn_id)
  File "/home/airflow/.local/lib/python3.8/site-packages/airflow/models/connection.py", line 477, in get_connection_from_secrets
    raise AirflowNotFoundException(f"The conn_id `{conn_id}` isn't defined")
airflow.exceptions.AirflowNotFoundException: The conn_id `movies_db_id` isn't defined
[2023-11-03T10:35:50.692+0000] {taskinstance.py:1398} INFO - Marking task as FAILED. dag_id=movies-etl-dag, task_id=get_updated_movies_ids, execution_date=20231103T103421, start_date=20231103T103550, end_date=20231103T103550
[2023-11-03T10:35:50.714+0000] {standard_task_runner.py:104} ERROR - Failed to execute job 9 for task get_updated_movies_ids (The conn_id `movies_db_id` isn't defined; 76)
[2023-11-03T10:35:50.734+0000] {local_task_job_runner.py:228} INFO - Task exited with return code 1
[2023-11-03T10:35:50.811+0000] {taskinstance.py:2776} INFO - 0 downstream tasks scheduled from follow-on schedule check
