[2023-11-02T16:07:02.026+0000] {taskinstance.py:1157} INFO - Dependencies all met for dep_context=non-requeueable deps ti=<TaskInstance: es-schemas-creation-dag.create_es_index manual__2023-11-02T16:04:44.885518+00:00 [queued]>
[2023-11-02T16:07:02.037+0000] {taskinstance.py:1157} INFO - Dependencies all met for dep_context=requeueable deps ti=<TaskInstance: es-schemas-creation-dag.create_es_index manual__2023-11-02T16:04:44.885518+00:00 [queued]>
[2023-11-02T16:07:02.038+0000] {taskinstance.py:1359} INFO - Starting attempt 2 of 2
[2023-11-02T16:07:02.060+0000] {taskinstance.py:1380} INFO - Executing <Task(PythonOperator): create_es_index> on 2023-11-02 16:04:44.885518+00:00
[2023-11-02T16:07:02.066+0000] {standard_task_runner.py:57} INFO - Started process 391 to run task
[2023-11-02T16:07:02.069+0000] {standard_task_runner.py:84} INFO - Running: ['***', 'tasks', 'run', 'es-schemas-creation-dag', 'create_es_index', 'manual__2023-11-02T16:04:44.885518+00:00', '--job-id', '5', '--raw', '--subdir', 'DAGS_FOLDER/create_es_indeces.py', '--cfg-path', '/tmp/tmpacnzljpd']
[2023-11-02T16:07:02.072+0000] {standard_task_runner.py:85} INFO - Job 5: Subtask create_es_index
[2023-11-02T16:07:02.256+0000] {task_command.py:415} INFO - Running <TaskInstance: es-schemas-creation-dag.create_es_index manual__2023-11-02T16:04:44.885518+00:00 [running]> on host 62132fa558d6
[2023-11-02T16:07:02.569+0000] {taskinstance.py:1660} INFO - Exporting env vars: AIRFLOW_CTX_DAG_OWNER='***' AIRFLOW_CTX_DAG_ID='es-schemas-creation-dag' AIRFLOW_CTX_TASK_ID='create_es_index' AIRFLOW_CTX_EXECUTION_DATE='2023-11-02T16:04:44.885518+00:00' AIRFLOW_CTX_TRY_NUMBER='2' AIRFLOW_CTX_DAG_RUN_ID='manual__2023-11-02T16:04:44.885518+00:00'
[2023-11-02T16:07:02.573+0000] {taskinstance.py:1935} ERROR - Task failed with exception
Traceback (most recent call last):
  File "/home/airflow/.local/lib/python3.8/site-packages/airflow/operators/python.py", line 192, in execute
    return_value = self.execute_callable()
  File "/home/airflow/.local/lib/python3.8/site-packages/airflow/operators/python.py", line 209, in execute_callable
    return self.python_callable(*self.op_args, **self.op_kwargs)
  File "/opt/airflow/dags/create_es_indeces.py", line 24, in create_es_index
    es_conn = es_hook.get_conn()
TypeError: 'Elasticsearch' object is not callable
[2023-11-02T16:07:02.624+0000] {taskinstance.py:1398} INFO - Marking task as FAILED. dag_id=es-schemas-creation-dag, task_id=create_es_index, execution_date=20231102T160444, start_date=20231102T160702, end_date=20231102T160702
[2023-11-02T16:07:02.640+0000] {standard_task_runner.py:104} ERROR - Failed to execute job 5 for task create_es_index ('Elasticsearch' object is not callable; 391)
[2023-11-02T16:07:02.687+0000] {local_task_job_runner.py:228} INFO - Task exited with return code 1
[2023-11-02T16:07:02.762+0000] {taskinstance.py:2776} INFO - 0 downstream tasks scheduled from follow-on schedule check
