[2023-11-03T13:13:50.083+0000] {taskinstance.py:1157} INFO - Dependencies all met for dep_context=non-requeueable deps ti=<TaskInstance: movies-etl-dag.write_to_es scheduled__2023-11-03T13:12:35.073204+00:00 [queued]>
[2023-11-03T13:13:50.094+0000] {taskinstance.py:1157} INFO - Dependencies all met for dep_context=requeueable deps ti=<TaskInstance: movies-etl-dag.write_to_es scheduled__2023-11-03T13:12:35.073204+00:00 [queued]>
[2023-11-03T13:13:50.095+0000] {taskinstance.py:1359} INFO - Starting attempt 1 of 1
[2023-11-03T13:13:50.111+0000] {taskinstance.py:1380} INFO - Executing <Task(PythonOperator): write_to_es> on 2023-11-03 13:12:35.073204+00:00
[2023-11-03T13:13:50.118+0000] {standard_task_runner.py:57} INFO - Started process 2636 to run task
[2023-11-03T13:13:50.122+0000] {standard_task_runner.py:84} INFO - Running: ['***', 'tasks', 'run', 'movies-etl-dag', 'write_to_es', 'scheduled__2023-11-03T13:12:35.073204+00:00', '--job-id', '83', '--raw', '--subdir', 'DAGS_FOLDER/movie_pg_es.py', '--cfg-path', '/tmp/tmpgv7akl92']
[2023-11-03T13:13:50.125+0000] {standard_task_runner.py:85} INFO - Job 83: Subtask write_to_es
[2023-11-03T13:13:50.308+0000] {task_command.py:415} INFO - Running <TaskInstance: movies-etl-dag.write_to_es scheduled__2023-11-03T13:12:35.073204+00:00 [running]> on host e468bf2dfd15
[2023-11-03T13:13:50.650+0000] {taskinstance.py:1660} INFO - Exporting env vars: AIRFLOW_CTX_DAG_OWNER='***' AIRFLOW_CTX_DAG_ID='movies-etl-dag' AIRFLOW_CTX_TASK_ID='write_to_es' AIRFLOW_CTX_EXECUTION_DATE='2023-11-03T13:12:35.073204+00:00' AIRFLOW_CTX_TRY_NUMBER='1' AIRFLOW_CTX_DAG_RUN_ID='scheduled__2023-11-03T13:12:35.073204+00:00'
[2023-11-03T13:13:50.737+0000] {taskinstance.py:1935} ERROR - Task failed with exception
Traceback (most recent call last):
  File "/home/airflow/.local/lib/python3.8/site-packages/airflow/operators/python.py", line 192, in execute
    return_value = self.execute_callable()
  File "/home/airflow/.local/lib/python3.8/site-packages/airflow/operators/python.py", line 209, in execute_callable
    return self.python_callable(*self.op_args, **self.op_kwargs)
  File "/opt/airflow/dags/movie_pg_es.py", line 113, in write_to_es
    films_data = [FilmWork(**json.loads(film_data)) for film_data in films_data]
  File "/opt/airflow/dags/movie_pg_es.py", line 113, in <listcomp>
    films_data = [FilmWork(**json.loads(film_data)) for film_data in films_data]
  File "/opt/airflow/dags/models.py", line 30, in __init__
    data["actors_ids"], data["actors_names"] = self.split_person_str(data["actors"])
KeyError: 'actors'
[2023-11-03T13:13:50.798+0000] {taskinstance.py:1398} INFO - Marking task as FAILED. dag_id=movies-etl-dag, task_id=write_to_es, execution_date=20231103T131235, start_date=20231103T131350, end_date=20231103T131350
[2023-11-03T13:13:50.823+0000] {standard_task_runner.py:104} ERROR - Failed to execute job 83 for task write_to_es ('actors'; 2636)
[2023-11-03T13:13:50.856+0000] {local_task_job_runner.py:228} INFO - Task exited with return code 1
[2023-11-03T13:13:50.920+0000] {taskinstance.py:2776} INFO - 0 downstream tasks scheduled from follow-on schedule check
