[2023-11-03T13:59:31.993+0000] {taskinstance.py:1157} INFO - Dependencies all met for dep_context=non-requeueable deps ti=<TaskInstance: movies-etl-dag.preprocess_data scheduled__2023-11-03T13:58:23.927579+00:00 [queued]>
[2023-11-03T13:59:32.005+0000] {taskinstance.py:1157} INFO - Dependencies all met for dep_context=requeueable deps ti=<TaskInstance: movies-etl-dag.preprocess_data scheduled__2023-11-03T13:58:23.927579+00:00 [queued]>
[2023-11-03T13:59:32.005+0000] {taskinstance.py:1359} INFO - Starting attempt 1 of 1
[2023-11-03T13:59:32.023+0000] {taskinstance.py:1380} INFO - Executing <Task(PythonOperator): preprocess_data> on 2023-11-03 13:58:23.927579+00:00
[2023-11-03T13:59:32.029+0000] {standard_task_runner.py:57} INFO - Started process 3568 to run task
[2023-11-03T13:59:32.035+0000] {standard_task_runner.py:84} INFO - Running: ['***', 'tasks', 'run', 'movies-etl-dag', 'preprocess_data', 'scheduled__2023-11-03T13:58:23.927579+00:00', '--job-id', '163', '--raw', '--subdir', 'DAGS_FOLDER/movie_pg_es.py', '--cfg-path', '/tmp/tmp3xdw37sd']
[2023-11-03T13:59:32.038+0000] {standard_task_runner.py:85} INFO - Job 163: Subtask preprocess_data
[2023-11-03T13:59:32.254+0000] {task_command.py:415} INFO - Running <TaskInstance: movies-etl-dag.preprocess_data scheduled__2023-11-03T13:58:23.927579+00:00 [running]> on host e468bf2dfd15
[2023-11-03T13:59:32.605+0000] {taskinstance.py:1660} INFO - Exporting env vars: AIRFLOW_CTX_DAG_OWNER='***' AIRFLOW_CTX_DAG_ID='movies-etl-dag' AIRFLOW_CTX_TASK_ID='preprocess_data' AIRFLOW_CTX_EXECUTION_DATE='2023-11-03T13:58:23.927579+00:00' AIRFLOW_CTX_TRY_NUMBER='1' AIRFLOW_CTX_DAG_RUN_ID='scheduled__2023-11-03T13:58:23.927579+00:00'
[2023-11-03T13:59:32.658+0000] {taskinstance.py:1935} ERROR - Task failed with exception
Traceback (most recent call last):
  File "/home/airflow/.local/lib/python3.8/site-packages/airflow/operators/python.py", line 192, in execute
    return_value = self.execute_callable()
  File "/home/airflow/.local/lib/python3.8/site-packages/airflow/operators/python.py", line 209, in execute_callable
    return self.python_callable(*self.op_args, **self.op_kwargs)
  File "/opt/airflow/dags/movie_pg_es.py", line 115, in preprocess_data
    film_data = FilmWorkPG(**json.loads(film_data))
  File "/home/airflow/.local/lib/python3.8/site-packages/pydantic/main.py", line 165, in __init__
    __pydantic_self__.__pydantic_validator__.validate_python(data, self_instance=__pydantic_self__)
pydantic_core._pydantic_core.ValidationError: 6 validation errors for FilmWorkPG
actors_names
  Input should be a valid list [type=list_type, input_value=None, input_type=NoneType]
    For further information visit https://errors.pydantic.dev/2.3/v/list_type
actors_ids
  Input should be a valid list [type=list_type, input_value=None, input_type=NoneType]
    For further information visit https://errors.pydantic.dev/2.3/v/list_type
writers_names
  Input should be a valid list [type=list_type, input_value=None, input_type=NoneType]
    For further information visit https://errors.pydantic.dev/2.3/v/list_type
writers_ids
  Input should be a valid list [type=list_type, input_value=None, input_type=NoneType]
    For further information visit https://errors.pydantic.dev/2.3/v/list_type
directors_names
  Input should be a valid list [type=list_type, input_value=None, input_type=NoneType]
    For further information visit https://errors.pydantic.dev/2.3/v/list_type
directors_ids
  Input should be a valid list [type=list_type, input_value=None, input_type=NoneType]
    For further information visit https://errors.pydantic.dev/2.3/v/list_type
[2023-11-03T13:59:32.710+0000] {taskinstance.py:1398} INFO - Marking task as FAILED. dag_id=movies-etl-dag, task_id=preprocess_data, execution_date=20231103T135823, start_date=20231103T135931, end_date=20231103T135932
[2023-11-03T13:59:32.727+0000] {standard_task_runner.py:104} ERROR - Failed to execute job 163 for task preprocess_data (6 validation errors for FilmWorkPG
actors_names
  Input should be a valid list [type=list_type, input_value=None, input_type=NoneType]
    For further information visit https://errors.pydantic.dev/2.3/v/list_type
actors_ids
  Input should be a valid list [type=list_type, input_value=None, input_type=NoneType]
    For further information visit https://errors.pydantic.dev/2.3/v/list_type
writers_names
  Input should be a valid list [type=list_type, input_value=None, input_type=NoneType]
    For further information visit https://errors.pydantic.dev/2.3/v/list_type
writers_ids
  Input should be a valid list [type=list_type, input_value=None, input_type=NoneType]
    For further information visit https://errors.pydantic.dev/2.3/v/list_type
directors_names
  Input should be a valid list [type=list_type, input_value=None, input_type=NoneType]
    For further information visit https://errors.pydantic.dev/2.3/v/list_type
directors_ids
  Input should be a valid list [type=list_type, input_value=None, input_type=NoneType]
    For further information visit https://errors.pydantic.dev/2.3/v/list_type; 3568)
[2023-11-03T13:59:32.769+0000] {local_task_job_runner.py:228} INFO - Task exited with return code 1
[2023-11-03T13:59:32.832+0000] {taskinstance.py:2776} INFO - 0 downstream tasks scheduled from follow-on schedule check
