[2023-11-03T10:51:23.585+0000] {taskinstance.py:1157} INFO - Dependencies all met for dep_context=non-requeueable deps ti=<TaskInstance: movies-etl-dag.get_updated_movies_ids scheduled__2023-11-03T10:50:21.125140+00:00 [queued]>
[2023-11-03T10:51:23.593+0000] {taskinstance.py:1157} INFO - Dependencies all met for dep_context=requeueable deps ti=<TaskInstance: movies-etl-dag.get_updated_movies_ids scheduled__2023-11-03T10:50:21.125140+00:00 [queued]>
[2023-11-03T10:51:23.594+0000] {taskinstance.py:1359} INFO - Starting attempt 1 of 1
[2023-11-03T10:51:23.615+0000] {taskinstance.py:1380} INFO - Executing <Task(PythonOperator): get_updated_movies_ids> on 2023-11-03 10:50:21.125140+00:00
[2023-11-03T10:51:23.622+0000] {standard_task_runner.py:57} INFO - Started process 359 to run task
[2023-11-03T10:51:23.625+0000] {standard_task_runner.py:84} INFO - Running: ['***', 'tasks', 'run', 'movies-etl-dag', 'get_updated_movies_ids', 'scheduled__2023-11-03T10:50:21.125140+00:00', '--job-id', '25', '--raw', '--subdir', 'DAGS_FOLDER/movie_pg_es.py', '--cfg-path', '/tmp/tmpvc2e64k9']
[2023-11-03T10:51:23.628+0000] {standard_task_runner.py:85} INFO - Job 25: Subtask get_updated_movies_ids
[2023-11-03T10:51:23.808+0000] {task_command.py:415} INFO - Running <TaskInstance: movies-etl-dag.get_updated_movies_ids scheduled__2023-11-03T10:50:21.125140+00:00 [running]> on host e468bf2dfd15
[2023-11-03T10:51:24.149+0000] {taskinstance.py:1660} INFO - Exporting env vars: AIRFLOW_CTX_DAG_OWNER='***' AIRFLOW_CTX_DAG_ID='movies-etl-dag' AIRFLOW_CTX_TASK_ID='get_updated_movies_ids' AIRFLOW_CTX_EXECUTION_DATE='2023-11-03T10:50:21.125140+00:00' AIRFLOW_CTX_TRY_NUMBER='1' AIRFLOW_CTX_DAG_RUN_ID='scheduled__2023-11-03T10:50:21.125140+00:00'
[2023-11-03T10:51:24.207+0000] {base.py:73} INFO - Using connection ID 'movies_db_id' for task execution.
[2023-11-03T10:51:24.298+0000] {movie_pg_es.py:53} INFO - Movies updated state: 0001-01-01 00:00:00
[2023-11-03T10:51:24.301+0000] {taskinstance.py:1935} ERROR - Task failed with exception
Traceback (most recent call last):
  File "/home/airflow/.local/lib/python3.8/site-packages/airflow/operators/python.py", line 192, in execute
    return_value = self.execute_callable()
  File "/home/airflow/.local/lib/python3.8/site-packages/airflow/operators/python.py", line 209, in execute_callable
    return self.python_callable(*self.op_args, **self.op_kwargs)
  File "/opt/airflow/dags/movie_pg_es.py", line 57, in get_updated_movies_ids
    ti.xcom_push(key=MOVIES_UPDATED_STATE_KEY, value=str(items[-1]["updated_at"]))
TypeError: tuple indices must be integers or slices, not str
[2023-11-03T10:51:24.349+0000] {taskinstance.py:1398} INFO - Marking task as FAILED. dag_id=movies-etl-dag, task_id=get_updated_movies_ids, execution_date=20231103T105021, start_date=20231103T105123, end_date=20231103T105124
[2023-11-03T10:51:24.368+0000] {standard_task_runner.py:104} ERROR - Failed to execute job 25 for task get_updated_movies_ids (tuple indices must be integers or slices, not str; 359)
[2023-11-03T10:51:24.400+0000] {local_task_job_runner.py:228} INFO - Task exited with return code 1
[2023-11-03T10:51:24.465+0000] {taskinstance.py:2776} INFO - 0 downstream tasks scheduled from follow-on schedule check
