[2023-11-03T13:58:30.921+0000] {taskinstance.py:1157} INFO - Dependencies all met for dep_context=non-requeueable deps ti=<TaskInstance: movies-etl-dag.preprocess_data scheduled__2023-11-03T13:57:23.927579+00:00 [queued]>
[2023-11-03T13:58:30.928+0000] {taskinstance.py:1157} INFO - Dependencies all met for dep_context=requeueable deps ti=<TaskInstance: movies-etl-dag.preprocess_data scheduled__2023-11-03T13:57:23.927579+00:00 [queued]>
[2023-11-03T13:58:30.929+0000] {taskinstance.py:1359} INFO - Starting attempt 1 of 1
[2023-11-03T13:58:30.944+0000] {taskinstance.py:1380} INFO - Executing <Task(PythonOperator): preprocess_data> on 2023-11-03 13:57:23.927579+00:00
[2023-11-03T13:58:30.952+0000] {standard_task_runner.py:57} INFO - Started process 3543 to run task
[2023-11-03T13:58:30.955+0000] {standard_task_runner.py:84} INFO - Running: ['***', 'tasks', 'run', 'movies-etl-dag', 'preprocess_data', 'scheduled__2023-11-03T13:57:23.927579+00:00', '--job-id', '160', '--raw', '--subdir', 'DAGS_FOLDER/movie_pg_es.py', '--cfg-path', '/tmp/tmpmh94k2v1']
[2023-11-03T13:58:30.958+0000] {standard_task_runner.py:85} INFO - Job 160: Subtask preprocess_data
[2023-11-03T13:58:31.145+0000] {task_command.py:415} INFO - Running <TaskInstance: movies-etl-dag.preprocess_data scheduled__2023-11-03T13:57:23.927579+00:00 [running]> on host e468bf2dfd15
[2023-11-03T13:58:31.500+0000] {taskinstance.py:1660} INFO - Exporting env vars: AIRFLOW_CTX_DAG_OWNER='***' AIRFLOW_CTX_DAG_ID='movies-etl-dag' AIRFLOW_CTX_TASK_ID='preprocess_data' AIRFLOW_CTX_EXECUTION_DATE='2023-11-03T13:57:23.927579+00:00' AIRFLOW_CTX_TRY_NUMBER='1' AIRFLOW_CTX_DAG_RUN_ID='scheduled__2023-11-03T13:57:23.927579+00:00'
[2023-11-03T13:58:31.551+0000] {taskinstance.py:1935} ERROR - Task failed with exception
Traceback (most recent call last):
  File "/home/airflow/.local/lib/python3.8/site-packages/airflow/operators/python.py", line 192, in execute
    return_value = self.execute_callable()
  File "/home/airflow/.local/lib/python3.8/site-packages/airflow/operators/python.py", line 209, in execute_callable
    return self.python_callable(*self.op_args, **self.op_kwargs)
  File "/opt/airflow/dags/movie_pg_es.py", line 115, in preprocess_data
    film_data = FilmWorkPG(**json.loads(film_data))
  File "/opt/airflow/dags/models.py", line 30, in __init__
    data["actors_ids"], data["actors_names"] = self.split_person_str(data["actors"])
KeyError: 'actors'
[2023-11-03T13:58:31.603+0000] {taskinstance.py:1398} INFO - Marking task as FAILED. dag_id=movies-etl-dag, task_id=preprocess_data, execution_date=20231103T135723, start_date=20231103T135830, end_date=20231103T135831
[2023-11-03T13:58:31.622+0000] {standard_task_runner.py:104} ERROR - Failed to execute job 160 for task preprocess_data ('actors'; 3543)
[2023-11-03T13:58:31.650+0000] {local_task_job_runner.py:228} INFO - Task exited with return code 1
[2023-11-03T13:58:31.715+0000] {taskinstance.py:2776} INFO - 0 downstream tasks scheduled from follow-on schedule check
