[2023-11-03T10:48:23.934+0000] {taskinstance.py:1157} INFO - Dependencies all met for dep_context=non-requeueable deps ti=<TaskInstance: movies-etl-dag.get_updated_movies_ids scheduled__2023-11-03T10:47:21.125140+00:00 [queued]>
[2023-11-03T10:48:23.941+0000] {taskinstance.py:1157} INFO - Dependencies all met for dep_context=requeueable deps ti=<TaskInstance: movies-etl-dag.get_updated_movies_ids scheduled__2023-11-03T10:47:21.125140+00:00 [queued]>
[2023-11-03T10:48:23.942+0000] {taskinstance.py:1359} INFO - Starting attempt 1 of 1
[2023-11-03T10:48:23.956+0000] {taskinstance.py:1380} INFO - Executing <Task(PythonOperator): get_updated_movies_ids> on 2023-11-03 10:47:21.125140+00:00
[2023-11-03T10:48:23.961+0000] {standard_task_runner.py:57} INFO - Started process 302 to run task
[2023-11-03T10:48:23.965+0000] {standard_task_runner.py:84} INFO - Running: ['***', 'tasks', 'run', 'movies-etl-dag', 'get_updated_movies_ids', 'scheduled__2023-11-03T10:47:21.125140+00:00', '--job-id', '22', '--raw', '--subdir', 'DAGS_FOLDER/movie_pg_es.py', '--cfg-path', '/tmp/tmpo97uzzb8']
[2023-11-03T10:48:23.967+0000] {standard_task_runner.py:85} INFO - Job 22: Subtask get_updated_movies_ids
[2023-11-03T10:48:24.130+0000] {task_command.py:415} INFO - Running <TaskInstance: movies-etl-dag.get_updated_movies_ids scheduled__2023-11-03T10:47:21.125140+00:00 [running]> on host e468bf2dfd15
[2023-11-03T10:48:24.375+0000] {taskinstance.py:1660} INFO - Exporting env vars: AIRFLOW_CTX_DAG_OWNER='***' AIRFLOW_CTX_DAG_ID='movies-etl-dag' AIRFLOW_CTX_TASK_ID='get_updated_movies_ids' AIRFLOW_CTX_EXECUTION_DATE='2023-11-03T10:47:21.125140+00:00' AIRFLOW_CTX_TRY_NUMBER='1' AIRFLOW_CTX_DAG_RUN_ID='scheduled__2023-11-03T10:47:21.125140+00:00'
[2023-11-03T10:48:24.421+0000] {base.py:73} INFO - Using connection ID 'movies_db_id' for task execution.
[2023-11-03T10:48:24.430+0000] {taskinstance.py:1935} ERROR - Task failed with exception
Traceback (most recent call last):
  File "/home/airflow/.local/lib/python3.8/site-packages/airflow/operators/python.py", line 192, in execute
    return_value = self.execute_callable()
  File "/home/airflow/.local/lib/python3.8/site-packages/airflow/operators/python.py", line 209, in execute_callable
    return self.python_callable(*self.op_args, **self.op_kwargs)
  File "/opt/airflow/dags/movie_pg_es.py", line 47, in get_updated_movies_ids
    pg_conn = pg_hook.get_conn()
  File "/home/airflow/.local/lib/python3.8/site-packages/airflow/providers/postgres/hooks/postgres.py", line 154, in get_conn
    self.conn = psycopg2.connect(**conn_args)
  File "/home/airflow/.local/lib/python3.8/site-packages/psycopg2/__init__.py", line 122, in connect
    conn = _connect(dsn, connection_factory=connection_factory, **kwasync)
psycopg2.OperationalError: connection to server at "movie_pg_db" (172.19.0.5), port 5432 failed: FATAL:  database "content" does not exist

[2023-11-03T10:48:24.476+0000] {taskinstance.py:1398} INFO - Marking task as FAILED. dag_id=movies-etl-dag, task_id=get_updated_movies_ids, execution_date=20231103T104721, start_date=20231103T104823, end_date=20231103T104824
[2023-11-03T10:48:24.491+0000] {standard_task_runner.py:104} ERROR - Failed to execute job 22 for task get_updated_movies_ids (connection to server at "movie_pg_db" (172.19.0.5), port 5432 failed: FATAL:  database "content" does not exist
; 302)
[2023-11-03T10:48:24.538+0000] {local_task_job_runner.py:228} INFO - Task exited with return code 1
[2023-11-03T10:48:24.602+0000] {taskinstance.py:2776} INFO - 0 downstream tasks scheduled from follow-on schedule check
